<?xml version="1.0" ?>
<!-- =================================================================================== -->
<!-- |    This document was autogenerated by xacro from robot_car.urdf.xacro           | -->
<!-- |    EDITING THIS FILE BY HAND IS NOT RECOMMENDED                                 | -->
<!-- =================================================================================== -->
<!-- Name your robot here -->
<robot name="robot_car">
  <link name="dummy_link"/>
  <joint name="dummy_link_joint=" type="fixed">
    <origin rpy="0 0 0" xyz="0 0 0"/>
    <parent link="dummy_link"/>
    <child link="base_link"/>
  </joint>
  <link name="base_link">
    <inertial>
      <origin rpy="0 0 0" xyz="-4.17816467845711E-06 0.155033500569797 0.0634993481602697"/>
      <mass value="47.0663452295482"/>
      <inertia ixx="4.22292908692067" ixy="-3.82540713050327E-05" ixz="2.17423066283378E-05" iyy="0.534699589034657" iyz="0.0172908433530719" izz="4.57389499567577"/>
    </inertial>
    <visual>
      <origin rpy="0 0 0" xyz="0 0 0"/>
      <geometry>
        <mesh filename="package://robot_car/meshes/base_link.STL"/>
      </geometry>
      <material name="">
        <color rgba="0.792156862745098 0.819607843137255 0.933333333333333 1"/>
      </material>
    </visual>
    <collision>
      <origin rpy="0 0 0" xyz="0 0 0"/>
      <geometry>
        <mesh filename="package://robot_car/meshes/base_link.STL"/>
      </geometry>
    </collision>
  </link>
  <link name="r_axle_link">
    <inertial>
      <origin rpy="0 0 0" xyz="0.044591 3.0732E-09 -0.044308"/>
      <mass value="0.54732"/>
      <inertia ixx="0.00019657" ixy="1.012E-10" ixz="0.00015844" iyy="0.0011746" iyz="-1.0367E-11" izz="0.0010774"/>
    </inertial>
    <visual>
      <origin rpy="0 0 0" xyz="0 0 0"/>
      <geometry>
        <mesh filename="package://robot_car/meshes/r_axle_link.STL"/>
      </geometry>
      <material name="">
        <color rgba="0.89804 0.91765 0.92941 1"/>
      </material>
    </visual>
    <collision>
      <origin rpy="0 0 0" xyz="0 0 0"/>
      <geometry>
        <mesh filename="package://robot_car/meshes/r_axle_link.STL"/>
      </geometry>
    </collision>
  </link>
  <joint name="r_axle_joint" type="revolute">
    <origin rpy="0 0 0" xyz="0.1016 0.43592 0.0762"/>
    <parent link="base_link"/>
    <child link="r_axle_link"/>
    <axis xyz="0 0 1"/>
    <limit effort="1000" lower="-0.61" upper="0.61" velocity="0.5"/>
  </joint>
  <link name="fr_wheel_link">
    <inertial>
      <origin rpy="0 0 0" xyz="5.5511E-17 2.4286E-17 -0.030426"/>
      <mass value="1.0025"/>
      <inertia ixx="0.0043607" ixy="-1.124E-18" ixz="8.2114E-19" iyy="0.0043607" iyz="-5.2661E-19" izz="0.0075093"/>
    </inertial>
    <visual>
      <origin rpy="0 0 0" xyz="0 0 0"/>
      <geometry>
        <mesh filename="package://robot_car/meshes/fr_wheel_link.STL"/>
      </geometry>
      <material name="">
        <color rgba="0.89804 0.91765 0.92941 1"/>
      </material>
    </visual>
    <collision>
      <origin rpy="0 0 0" xyz="0 0 0"/>
      <geometry>
        <mesh filename="package://robot_car/meshes/fr_wheel_link.STL"/>
      </geometry>
    </collision>
  </link>
  <joint name="fr_wheel_joint" type="continuous">
    <origin rpy="1.5708 0 1.5708" xyz="0.127 0 -0.0508"/>
    <parent link="r_axle_link"/>
    <child link="fr_wheel_link"/>
    <axis xyz="0 0 1"/>
    <limit effort="1000" velocity="0.5"/>
  </joint>
  <link name="l_axle_link">
    <inertial>
      <origin rpy="0 0 0" xyz="-0.0445911447038466 -3.07316860848061E-09 -0.0443082836786182"/>
      <mass value="0.547317633847802"/>
      <inertia ixx="0.000196574365269895" ixy="1.01203737038273E-10" ixz="-0.000158436445636198" iyy="0.0011746456902795" iyz="1.03666036366386E-11" izz="0.00107738190106747"/>
    </inertial>
    <visual>
      <origin rpy="0 0 0" xyz="0 0 0"/>
      <geometry>
        <mesh filename="package://robot_car/meshes/l_axle_link.STL"/>
      </geometry>
      <material name="">
        <color rgba="0.898039215686275 0.917647058823529 0.929411764705882 1"/>
      </material>
    </visual>
    <collision>
      <origin rpy="0 0 0" xyz="0 0 0"/>
      <geometry>
        <mesh filename="package://robot_car/meshes/l_axle_link.STL"/>
      </geometry>
    </collision>
  </link>
  <joint name="l_axle_joint" type="revolute">
    <origin rpy="0 0 0" xyz="-0.1016 0.43592 0.0762"/>
    <parent link="base_link"/>
    <child link="l_axle_link"/>
    <axis xyz="0 0 1"/>
    <limit effort="1000" lower="-0.61" upper="0.61" velocity="0.5"/>
  </joint>
  <link name="fl_wheel_link">
    <inertial>
      <origin rpy="0 0 0" xyz="-1.66533453693773E-16 -6.93889390390723E-18 -0.0304263623336742"/>
      <mass value="1.00248274433347"/>
      <inertia ixx="0.0043607050487617" ixy="-8.55490495270943E-20" ixz="-3.06179300718463E-19" iyy="0.0043607050487617" iyz="3.75228321009424E-20" izz="0.00750931140654651"/>
    </inertial>
    <visual>
      <origin rpy="0 0 0" xyz="0 0 0"/>
      <geometry>
        <mesh filename="package://robot_car/meshes/fl_wheel_link.STL"/>
      </geometry>
      <material name="">
        <color rgba="0.898039215686275 0.917647058823529 0.929411764705882 1"/>
      </material>
    </visual>
    <collision>
      <origin rpy="0 0 0" xyz="0 0 0"/>
      <geometry>
        <mesh filename="package://robot_car/meshes/fl_wheel_link.STL"/>
      </geometry>
    </collision>
  </link>
  <joint name="fl_wheel_joint" type="continuous">
    <origin rpy="1.5708 0 -1.5708" xyz="-0.127 0 -0.0508"/>
    <parent link="l_axle_link"/>
    <child link="fl_wheel_link"/>
    <axis xyz="0 0 1"/>
    <limit effort="1000" velocity="0.5"/>
  </joint>
  <link name="rl_wheel_link">
    <inertial>
      <origin rpy="0 0 0" xyz="0 3.46944695195361E-18 -0.0304263623336755"/>
      <mass value="1.00248274433346"/>
      <inertia ixx="0.00436070504876117" ixy="1.25628055531491E-19" ixz="1.66648897421017E-19" iyy="0.00436070504876117" iyz="2.6082222710412E-20" izz="0.0075093114065465"/>
    </inertial>
    <visual>
      <origin rpy="0 0 0" xyz="0 0 0"/>
      <geometry>
        <mesh filename="package://robot_car/meshes/rl_wheel_link.STL"/>
      </geometry>
      <material name="">
        <color rgba="0.898039215686275 0.917647058823529 0.929411764705882 1"/>
      </material>
    </visual>
    <collision>
      <origin rpy="0 0 0" xyz="0 0 0"/>
      <geometry>
        <mesh filename="package://robot_car/meshes/rl_wheel_link.STL"/>
      </geometry>
    </collision>
  </link>
  <joint name="rl_wheel_joint" type="continuous">
    <origin rpy="1.5708 0 -1.5708" xyz="-0.2286 -0.072078 0.0254"/>
    <parent link="base_link"/>
    <child link="rl_wheel_link"/>
    <axis xyz="0 0 1"/>
    <limit effort="1000" velocity="0.5"/>
  </joint>
  <link name="rr_wheel_link">
    <inertial>
      <origin rpy="0 0 0" xyz="0 6.93889390390723E-18 -0.0304263623336748"/>
      <mass value="1.00248274433347"/>
      <inertia ixx="0.00436070504876132" ixy="2.78391771057784E-18" ixz="-7.84595195846635E-19" iyy="0.00436070504876133" iyz="-8.62640522217282E-19" izz="0.00750931140654648"/>
    </inertial>
    <visual>
      <origin rpy="0 0 0" xyz="0 0 0"/>
      <geometry>
        <mesh filename="package://robot_car/meshes/rr_wheel_link.STL"/>
      </geometry>
      <material name="">
        <color rgba="0.898039215686275 0.917647058823529 0.929411764705882 1"/>
      </material>
    </visual>
    <collision>
      <origin rpy="0 0 0" xyz="0 0 0"/>
      <geometry>
        <mesh filename="package://robot_car/meshes/rr_wheel_link.STL"/>
      </geometry>
    </collision>
  </link>
  <joint name="rr_wheel_joint" type="continuous">
    <origin rpy="1.5708 0 1.5708" xyz="0.2286 -0.072078 0.0254"/>
    <parent link="base_link"/>
    <child link="rr_wheel_link"/>
    <axis xyz="0 0 -1"/>
    <limit effort="100" velocity="0.5"/>
  </joint>
  <transmission name="fr_trans">
    <type>transmission_interface/SimpleTransmission</type>
    <joint name="r_axle_joint">
      <hardwareInterface>hardware_interface/EffortJointInterface</hardwareInterface>
    </joint>
    <actuator name="fr_steering">
      <mechanicalReduction>50</mechanicalReduction>
      <hardwareInterface>hardware_interface/EffortJointInterface</hardwareInterface>
    </actuator>
  </transmission>
  <transmission name="fl_trans">
    <type>transmission_interface/SimpleTransmission</type>
    <joint name="l_axle_joint">
      <hardwareInterface>hardware_interface/EffortJointInterface</hardwareInterface>
    </joint>
    <actuator name="fl_steering">
      <mechanicalReduction>50</mechanicalReduction>
      <hardwareInterface>hardware_interface/EffortJointInterface</hardwareInterface>
    </actuator>
  </transmission>
  <transmission name="rr_trans">
    <type>transmission_interface/SimpleTransmission</type>
    <joint name="rr_wheel_joint">
      <hardwareInterface>hardware_interface/VelocityJointInterface</hardwareInterface>
    </joint>
    <actuator name="rr_wheel">
      <mechanicalReduction>50</mechanicalReduction>
      <hardwareInterface>hardware_interface/VelocityJointInterface</hardwareInterface>
    </actuator>
  </transmission>
  <transmission name="rl_trans">
    <type>transmission_interface/SimpleTransmission</type>
    <joint name="rl_wheel_joint">
      <hardwareInterface>hardware_interface/VelocityJointInterface</hardwareInterface>
    </joint>
    <actuator name="rl_wheel">
      <mechanicalReduction>50</mechanicalReduction>
      <hardwareInterface>hardware_interface/VelocityJointInterface</hardwareInterface>
    </actuator>
  </transmission>
  <link name="base_laser">
    <inertial>
      <origin rpy="0 0 0" xyz="-0.00029774 0.0066667 0.00013047"/>
      <mass value="0.15717"/>
      <inertia ixx="6.7885E-05" ixy="-1.3987E-07" ixz="-8.1554E-07" iyy="0.00013173" iyz="-9.0932E-08" izz="7.1972E-05"/>
    </inertial>
    <visual>
      <origin rpy="0 0 0" xyz="0 0 0"/>
      <geometry>
        <mesh filename="package://robot_car/meshes/ydlidar.dae"/>
      </geometry>
      <material name="">
        <color rgba="0.64706 0.61961 0.58824 1"/>
      </material>
    </visual>
    <collision>
      <origin rpy="0 0 0" xyz="0 0 0"/>
      <geometry>
        <mesh filename="package://robot_car/meshes/ydlidar.dae"/>
      </geometry>
    </collision>
  </link>
  <link name="laser_frame">
    <inertial>
      <origin rpy="0 0 0" xyz="-0.00036659 0.00064155 -0.00027052"/>
      <mass value="0.25482"/>
      <inertia ixx="8.9194E-05" ixy="1.8116E-07" ixz="3.6435E-08" iyy="0.00018279" iyz="2.423E-07" izz="0.00011103"/>
    </inertial>
    <!--visual>
      <origin
        xyz="0 0 0"
        rpy="0 0 0" />
      <geometry>
        <mesh
          filename="package://robot_car/meshes/ydlidar.dae" />
      </geometry>
      <material
        name="">
        <color
          rgba="0.64706 0.61961 0.58824 1" />
      </material>
    </visual-->
    <!--collision>
      <origin
        xyz="0 0 0"
        rpy="0 0 0" />
      <geometry>
        <mesh
          filename="package://robot_car/meshes/ydlidar.dae" />
      </geometry>
    </collision-->
  </link>
  <joint name="laser_joint" type="fixed">
    <origin rpy="0 0 0" xyz="0 0 0.03172"/>
    <parent link="base_laser"/>
    <child link="laser_frame"/>
    <axis xyz="0 0 0"/>
  </joint>
  <!-- Add your gazebo sensors here -->
  <gazebo reference="base_laser">
    <!-- <gravity>true</gravity> -->
    <!-- Gazebo has fixed set of Sensors types. Check them out here <> -->
    <sensor name="laser" type="ray">
      <!-- Add in your sensor characteristics -->
      <pose> 0 0 0 0 0 0 </pose>
      <visualise>true</visualise>
      <update_rate>40</update_rate>
      <!-- <always_on>true</always_on> -->
      <ray>
        <scan>
          <horizontal>
            <samples>720</samples>
            <resolution>1</resolution>
            <min_angle>-1.570796</min_angle>
            <max_angle>1.570796</max_angle>
          </horizontal>
        </scan>
        <range>
          <min>0.10</min>
          <max>30.0</max>
          <resolution>0.01</resolution>
        </range>
        <noise>
          <type>gaussian</type>
          <mean>0.0</mean>
          <stddev>0.01</stddev>
        </noise>
      </ray>
      <plugin filename="libgazebo_ros_laser.so" name="gazebo_ros_head_hokuyo_controller">
        <!-- Use topic name as /my_robot/scan -->
        <topicName>/robot_car/scan</topicName>
        <frameName>laser_frame</frameName>
      </plugin>
    </sensor>
  </gazebo>
  <!--  Gazebo plugin for control here is already added for you -->
  <gazebo>
    <plugin filename="libgazebo_ros_control.so" name="gazebo_ros_control">
      <robotNamespace>/robot_car</robotNamespace>
      <robotSimType>gazebo_ros_control/DefaultRobotHWSim</robotSimType>
      <legacyModeNS>true</legacyModeNS>
    </plugin>
  </gazebo>
  <!-- Create a joint between your robot and sensor -->
  <joint name="lidar_joint" type="fixed">
    <origin rpy="0 0 0" xyz="0 0 0.345"/>
    <parent link="base_link"/>
    <child link="base_laser"/>
    <axis xyz="0 0 0"/>
  </joint>
</robot>
