<?xml version="1.0" encoding="utf-8"?>
<!-- This URDF was automatically created by SolidWorks to URDF Exporter! Originally created by Stephen Brawner (brawner@gmail.com) 
     Commit Version: 1.6.0-4-g7f85cfe  Build Version: 1.6.7995.38578
     For more information, please see http://wiki.ros.org/sw_urdf_exporter -->
<robot
  name="robot_car">

  <link name="dummy_link" />

  <joint name="dummy_link_joint=" type="fixed">
    <origin
      xyz="0 0 0"
      rpy="0 0 0" />
    <parent link="dummy_link"/>
    <child link="base_link"/>
  </joint>

  <link
    name="base_link">
    <inertial>
      <origin
        xyz="-4.17816467845711E-06 0.155033500569797 0.0634993481602697"
        rpy="0 0 0" />
      <mass
        value="47.0663452295482" />
      <inertia
        ixx="4.22292908692067"
        ixy="-3.82540713050327E-05"
        ixz="2.17423066283378E-05"
        iyy="0.534699589034657"
        iyz="0.0172908433530719"
        izz="4.57389499567577" />
    </inertial>
    <visual>
      <origin
        xyz="0 0 0"
        rpy="0 0 0" />
      <geometry>
        <mesh
          filename="package://robot_car/meshes/base_link.STL" />
      </geometry>
      <material
        name="">
        <color
          rgba="0.0 0.0 1 1" />
      </material>
    </visual>
    <collision>
      <origin
        xyz="0 0 0"
        rpy="0 0 0" />
      <geometry>
        <mesh
          filename="package://robot_car/meshes/base_link.STL" />
      </geometry>
    </collision>
  </link>
  <link
    name="r_axle_link">
    <inertial>
      <origin
        xyz="0.044591 3.0732E-09 -0.044308"
        rpy="0 0 0" />
      <mass
        value="0.54732" />
      <inertia
        ixx="0.00019657"
        ixy="1.012E-10"
        ixz="0.00015844"
        iyy="0.0011746"
        iyz="-1.0367E-11"
        izz="0.0010774" />
    </inertial>
    <visual>
      <origin
        xyz="0 0 0"
        rpy="0 0 0" />
      <geometry>
        <mesh
          filename="package://robot_car/meshes/r_axle_link.STL" />
      </geometry>
      <material
        name="">
        <color
          rgba="1 1 1 1" />
      </material>
    </visual>
    <collision>
      <origin
        xyz="0 0 0"
        rpy="0 0 0" />
      <geometry>
        <mesh
          filename="package://robot_car/meshes/r_axle_link.STL" />
      </geometry>
    </collision>
  </link>
  <joint
    name="r_axle_joint"
    type="revolute">
    <origin
      xyz="0.1016 0.43592 0.0762"
      rpy="0 0 0" />
    <parent
      link="base_link" />
    <child
      link="r_axle_link" />
    <axis
      xyz="0 0 1" />
    <limit
      lower="-0.61"
      upper="0.61"
      effort="1000"
      velocity="0.5" />
  </joint>
  <link
    name="fr_wheel_link">
    <inertial>
      <origin
        xyz="5.5511E-17 2.4286E-17 -0.030426"
        rpy="0 0 0" />
      <mass
        value="1.0025" />
      <inertia
        ixx="0.0043607"
        ixy="-1.124E-18"
        ixz="8.2114E-19"
        iyy="0.0043607"
        iyz="-5.2661E-19"
        izz="0.0075093" />
    </inertial>
    <visual>
      <origin
        xyz="0 0 0"
        rpy="0 0 0" />
      <geometry>
        <mesh
          filename="package://robot_car/meshes/fr_wheel_link.STL" />
      </geometry>
      <material
        name="">
        <color
          rgba="1 1 1 1" />
      </material>
    </visual>
    <collision>
      <origin
        xyz="0 0 0"
        rpy="0 0 0" />
      <geometry>
        <mesh
          filename="package://robot_car/meshes/fr_wheel_link.STL" />
      </geometry>
    </collision>
  </link>
  <joint
    name="fr_wheel_joint"
    type="continuous">
    <origin
      xyz="0.127 0 -0.0508"
      rpy="1.5708 0 1.5708" />
    <parent
      link="r_axle_link" />
    <child
      link="fr_wheel_link" />
    <axis
      xyz="0 0 1" />
    <limit
      effort="1"
      velocity="1000" />
  </joint>
  <link
    name="l_axle_link">
    <inertial>
      <origin
        xyz="-0.0445911447038466 -3.07316860848061E-09 -0.0443082836786182"
        rpy="0 0 0" />
      <mass
        value="0.547317633847802" />
      <inertia
        ixx="0.000196574365269895"
        ixy="1.01203737038273E-10"
        ixz="-0.000158436445636198"
        iyy="0.0011746456902795"
        iyz="1.03666036366386E-11"
        izz="0.00107738190106747" />
    </inertial>
    <visual>
      <origin
        xyz="0 0 0"
        rpy="0 0 0" />
      <geometry>
        <mesh
          filename="package://robot_car/meshes/l_axle_link.STL" />
      </geometry>
      <material
        name="">
        <color
          rgba="1 1 1 1" />
      </material>
    </visual>
    <collision>
      <origin
        xyz="0 0 0"
        rpy="0 0 0" />
      <geometry>
        <mesh
          filename="package://robot_car/meshes/l_axle_link.STL" />
      </geometry>
    </collision>
  </link>
  <joint
    name="l_axle_joint"
    type="revolute">
    <origin
      xyz="-0.1016 0.43592 0.0762"
      rpy="0 0 0" />
    <parent
      link="base_link" />
    <child
      link="l_axle_link" />
    <axis
      xyz="0 0 1" />
    <limit
      lower="-0.61"
      upper="0.61"
      effort="1000"
      velocity="0.5" />
  </joint>
  <link
    name="fl_wheel_link">
    <inertial>
      <origin
        xyz="-1.66533453693773E-16 -6.93889390390723E-18 -0.0304263623336742"
        rpy="0 0 0" />
      <mass
        value="1.00248274433347" />
      <inertia
        ixx="0.0043607050487617"
        ixy="-8.55490495270943E-20"
        ixz="-3.06179300718463E-19"
        iyy="0.0043607050487617"
        iyz="3.75228321009424E-20"
        izz="0.00750931140654651" />
    </inertial>
    <visual>
      <origin
        xyz="0 0 0"
        rpy="0 0 0" />
      <geometry>
        <mesh
          filename="package://robot_car/meshes/fl_wheel_link.STL" />
      </geometry>
      <material
        name="">
        <color
          rgba="1 1 1 1" />
      </material>
    </visual>
    <collision>
      <origin
        xyz="0 0 0"
        rpy="0 0 0" />
      <geometry>
        <mesh
          filename="package://robot_car/meshes/fl_wheel_link.STL" />
      </geometry>
    </collision>
  </link>
  <joint
    name="fl_wheel_joint"
    type="continuous">
    <origin
      xyz="-0.127 0 -0.0508"
      rpy="1.5708 0 -1.5708" />
    <parent
      link="l_axle_link" />
    <child
      link="fl_wheel_link" />
    <axis
      xyz="0 0 1" />
    <limit
      effort="1"
      velocity="1000" />
  </joint>
  <link
    name="rl_wheel_link">
    <inertial>
      <origin
        xyz="0 3.46944695195361E-18 -0.0304263623336755"
        rpy="0 0 0" />
      <mass
        value="1.00248274433346" />
      <inertia
        ixx="0.00436070504876117"
        ixy="1.25628055531491E-19"
        ixz="1.66648897421017E-19"
        iyy="0.00436070504876117"
        iyz="2.6082222710412E-20"
        izz="0.0075093114065465" />
    </inertial>
    <visual>
      <origin
        xyz="0 0 0"
        rpy="0 0 0" />
      <geometry>
        <mesh
          filename="package://robot_car/meshes/rl_wheel_link.STL" />
      </geometry>
      <material
        name="">
        <color
          rgba="1 1 1 1" />
      </material>
    </visual>
    <collision>
      <origin
        xyz="0 0 0"
        rpy="0 0 0" />
      <geometry>
        <mesh
          filename="package://robot_car/meshes/rl_wheel_link.STL" />
      </geometry>
    </collision>
  </link>
  <joint
    name="rl_wheel_joint"
    type="continuous">
    <origin
      xyz="-0.2286 -0.072078 0.0254"
      rpy="1.5708 0 -1.5708" />
    <parent
      link="base_link" />
    <child
      link="rl_wheel_link" />
    <axis
      xyz="0 0 1" />
    <limit
      effort="1"
      velocity="1000" />
  </joint>
  <link
    name="rr_wheel_link">
    <inertial>
      <origin
        xyz="0 6.93889390390723E-18 -0.0304263623336748"
        rpy="0 0 0" />
      <mass
        value="1.00248274433347" />
      <inertia
        ixx="0.00436070504876132"
        ixy="2.78391771057784E-18"
        ixz="-7.84595195846635E-19"
        iyy="0.00436070504876133"
        iyz="-8.62640522217282E-19"
        izz="0.00750931140654648" />
    </inertial>
    <visual>
      <origin
        xyz="0 0 0"
        rpy="0 0 0" />
      <geometry>
        <mesh
          filename="package://robot_car/meshes/rr_wheel_link.STL" />
      </geometry>
      <material
        name="">
        <color
          rgba="1 1 1 1" />
      </material>
    </visual>
    <collision>
      <origin
        xyz="0 0 0"
        rpy="0 0 0" />
      <geometry>
        <mesh
          filename="package://robot_car/meshes/rr_wheel_link.STL" />
      </geometry>
    </collision>
  </link>
  <joint
    name="rr_wheel_joint"
    type="continuous">
    <origin
      xyz="0.2286 -0.072078 0.0254"
      rpy="1.5708 0 1.5708" />
    <parent
      link="base_link" />
    <child
      link="rr_wheel_link" />
    <axis
      xyz="0 0 -1" />
    <limit
      effort="1"
      velocity="1000" />
  </joint>


  <transmission name="fr_trans">
    <type>transmission_interface/SimpleTransmission</type>
    <joint name="r_axle_joint">
      <hardwareInterface>hardware_interface/EffortJointInterface</hardwareInterface>
    </joint>
    <actuator name="fr_steering">
      <mechanicalReduction>50</mechanicalReduction>
      <hardwareInterface>hardware_interface/EffortJointInterface</hardwareInterface>
    </actuator>
  </transmission>
  
  <transmission name="fl_trans">
    <type>transmission_interface/SimpleTransmission</type>
    <joint name="l_axle_joint">
      <hardwareInterface>hardware_interface/EffortJointInterface</hardwareInterface>
    </joint>
    <actuator name="fl_steering">
      <mechanicalReduction>50</mechanicalReduction>
      <hardwareInterface>hardware_interface/EffortJointInterface</hardwareInterface>
    </actuator>
  </transmission>
  
  <transmission name="rr_trans">
    <type>transmission_interface/SimpleTransmission</type>
    <joint name="rr_wheel_joint">
      <hardwareInterface>hardware_interface/VelocityJointInterface</hardwareInterface>
    </joint>
    <actuator name="rr_wheel">
      <mechanicalReduction>50</mechanicalReduction>
      <hardwareInterface>hardware_interface/VelocityJointInterface</hardwareInterface>
    </actuator>
  </transmission>
  
  <transmission name="rl_trans">
    <type>transmission_interface/SimpleTransmission</type>
    <joint name="rl_wheel_joint">
      <hardwareInterface>hardware_interface/VelocityJointInterface</hardwareInterface>
    </joint>
    <actuator name="rl_wheel">
      <mechanicalReduction>50</mechanicalReduction>
      <hardwareInterface>hardware_interface/VelocityJointInterface</hardwareInterface>
    </actuator>
  </transmission>
</robot>
